#if PROTO_PROMISE_DEBUG_ENABLE || (!PROTO_PROMISE_DEBUG_DISABLE && DEBUG)
#define PROMISE_DEBUG
#else
#undef PROMISE_DEBUG
#endif
#if !PROTO_PROMISE_PROGRESS_DISABLE
#define PROMISE_PROGRESS
#else
#undef PROMISE_PROGRESS
# endif

using NUnit.Framework;
using Proto.Promises;
using Proto.Promises.Threading;
using ProtoPromiseTests.Concurrency;
using System.Collections.Generic;
using System.Linq;
using System.Runtime.CompilerServices;
using System.Threading;

namespace ProtoPromiseTests.APIs
{
    public class MiscellaneousTests
    {
        [SetUp]
        public void Setup()
        {
            TestHelper.Setup();
        }

        [TearDown]
        public void Teardown()
        {
            TestHelper.Cleanup();

            TestHelper.s_expectedUncaughtRejectValue = null;
        }

        [Test]
        public void PromiseIsInvalidAfterAwaited_void()
        {
            var deferred = Promise.NewDeferred();
            var promise = deferred.Promise;

            Assert.IsTrue(promise.IsValid);

            promise.Then(() => { }).Forget();

            Assert.IsFalse(promise.IsValid);

#if CSHARP_7_3_OR_NEWER && PROMISE_DEBUG
            Assert.Throws<InvalidOperationException>(() => promise.GetAwaiter());
#endif
            Assert.Throws<InvalidOperationException>(() => promise.Preserve());
            Assert.Throws<InvalidOperationException>(() => promise.Forget());
            Assert.Throws<InvalidOperationException>(() => promise.Duplicate());

#if PROMISE_PROGRESS
            Assert.Throws<InvalidOperationException>(() => promise.Progress(v => { }));
            Assert.Throws<InvalidOperationException>(() => promise.Progress(1, (cv, v) => { }));
#endif
            Assert.Throws<InvalidOperationException>(() => promise.CatchCancelation(() => { }));
            Assert.Throws<InvalidOperationException>(() => promise.CatchCancelation(1, cv => { }));

            Assert.Throws<InvalidOperationException>(() => promise.Finally(() => { }));
            Assert.Throws<InvalidOperationException>(() => promise.Finally(1, cv => { }));

            Assert.Throws<InvalidOperationException>(() => promise.ContinueWith(r => { }));
            Assert.Throws<InvalidOperationException>(() => promise.ContinueWith(r => 1));
            Assert.Throws<InvalidOperationException>(() => promise.ContinueWith(r => Promise.Resolved()));
            Assert.Throws<InvalidOperationException>(() => promise.ContinueWith(r => Promise.Resolved(1)));
            Assert.Throws<InvalidOperationException>(() => promise.ContinueWith(1, (cv, r) => { }));
            Assert.Throws<InvalidOperationException>(() => promise.ContinueWith(1, (cv, r) => 1));
            Assert.Throws<InvalidOperationException>(() => promise.ContinueWith(1, (cv, r) => Promise.Resolved()));
            Assert.Throws<InvalidOperationException>(() => promise.ContinueWith(1, (cv, r) => Promise.Resolved(1)));

            Assert.Throws<InvalidOperationException>(() => promise.Catch(() => { }));
            Assert.Throws<InvalidOperationException>(() => promise.Catch(() => Promise.Resolved()));
            Assert.Throws<InvalidOperationException>(() => promise.Catch((object r) => { }));
            Assert.Throws<InvalidOperationException>(() => promise.Catch((object r) => Promise.Resolved()));
            Assert.Throws<InvalidOperationException>(() => promise.Catch(1, cv => { }));
            Assert.Throws<InvalidOperationException>(() => promise.Catch(1, cv => Promise.Resolved()));
            Assert.Throws<InvalidOperationException>(() => promise.Catch(1, (int cv, object r) => { }));
            Assert.Throws<InvalidOperationException>(() => promise.Catch(1, (int cv, object r) => Promise.Resolved()));

            Assert.Throws<InvalidOperationException>(() => promise.Then(() => { }));
            Assert.Throws<InvalidOperationException>(() => promise.Then(() => 1));
            Assert.Throws<InvalidOperationException>(() => promise.Then(() => Promise.Resolved()));
            Assert.Throws<InvalidOperationException>(() => promise.Then(() => Promise.Resolved(1)));
            Assert.Throws<InvalidOperationException>(() => promise.Then(1, cv => { }));
            Assert.Throws<InvalidOperationException>(() => promise.Then(1, cv => 1));
            Assert.Throws<InvalidOperationException>(() => promise.Then(1, cv => Promise.Resolved()));
            Assert.Throws<InvalidOperationException>(() => promise.Then(1, cv => Promise.Resolved(1)));

            Assert.Throws<InvalidOperationException>(() => promise.Then(() => { }, () => { }));
            Assert.Throws<InvalidOperationException>(() => promise.Then(() => 1, () => 1));
            Assert.Throws<InvalidOperationException>(() => promise.Then(() => Promise.Resolved(), () => { }));
            Assert.Throws<InvalidOperationException>(() => promise.Then(() => Promise.Resolved(1), () => 1));
            Assert.Throws<InvalidOperationException>(() => promise.Then(1, cv => { }, () => { }));
            Assert.Throws<InvalidOperationException>(() => promise.Then(1, cv => 1, () => 1));
            Assert.Throws<InvalidOperationException>(() => promise.Then(1, cv => Promise.Resolved(), () => { }));
            Assert.Throws<InvalidOperationException>(() => promise.Then(1, cv => Promise.Resolved(1), () => 1));

            Assert.Throws<InvalidOperationException>(() => promise.Then(() => { }, 1, cv => { }));
            Assert.Throws<InvalidOperationException>(() => promise.Then(() => 1, 1, cv => 1));
            Assert.Throws<InvalidOperationException>(() => promise.Then(() => Promise.Resolved(), 1, cv => { }));
            Assert.Throws<InvalidOperationException>(() => promise.Then(() => Promise.Resolved(1), 1, cv => 1));
            Assert.Throws<InvalidOperationException>(() => promise.Then(1, cv => { }, 1, cv => { }));
            Assert.Throws<InvalidOperationException>(() => promise.Then(1, cv => 1, 1, cv => 1));
            Assert.Throws<InvalidOperationException>(() => promise.Then(1, cv => Promise.Resolved(), 1, cv => { }));
            Assert.Throws<InvalidOperationException>(() => promise.Then(1, cv => Promise.Resolved(1), 1, cv => 1));

            Assert.Throws<InvalidOperationException>(() => promise.Then(() => { }, (object r) => { }));
            Assert.Throws<InvalidOperationException>(() => promise.Then(() => 1, (object r) => 1));
            Assert.Throws<InvalidOperationException>(() => promise.Then(() => Promise.Resolved(), (object r) => { }));
            Assert.Throws<InvalidOperationException>(() => promise.Then(() => Promise.Resolved(1), (object r) => 1));
            Assert.Throws<InvalidOperationException>(() => promise.Then(1, cv => { }, (object r) => { }));
            Assert.Throws<InvalidOperationException>(() => promise.Then(1, cv => 1, (object r) => 1));
            Assert.Throws<InvalidOperationException>(() => promise.Then(1, cv => Promise.Resolved(), (object r) => { }));
            Assert.Throws<InvalidOperationException>(() => promise.Then(1, cv => Promise.Resolved(1), (object r) => 1));

            Assert.Throws<InvalidOperationException>(() => promise.Then(() => { }, 1, (int cv, object r) => { }));
            Assert.Throws<InvalidOperationException>(() => promise.Then(() => 1, 1, (int cv, object r) => 1));
            Assert.Throws<InvalidOperationException>(() => promise.Then(() => Promise.Resolved(), 1, (int cv, object r) => { }));
            Assert.Throws<InvalidOperationException>(() => promise.Then(() => Promise.Resolved(1), 1, (int cv, object r) => 1));
            Assert.Throws<InvalidOperationException>(() => promise.Then(1, cv => { }, 1, (int cv, object r) => { }));
            Assert.Throws<InvalidOperationException>(() => promise.Then(1, cv => 1, 1, (int cv, object r) => 1));
            Assert.Throws<InvalidOperationException>(() => promise.Then(1, cv => Promise.Resolved(), 1, (int cv, object r) => { }));
            Assert.Throws<InvalidOperationException>(() => promise.Then(1, cv => Promise.Resolved(1), 1, (int cv, object r) => 1));

            Assert.Throws<InvalidOperationException>(() => promise.Then(() => { }, () => Promise.Resolved()));
            Assert.Throws<InvalidOperationException>(() => promise.Then(() => 1, () => Promise.Resolved(1)));
            Assert.Throws<InvalidOperationException>(() => promise.Then(() => Promise.Resolved(), () => Promise.Resolved()));
            Assert.Throws<InvalidOperationException>(() => promise.Then(() => Promise.Resolved(1), () => Promise.Resolved(1)));
            Assert.Throws<InvalidOperationException>(() => promise.Then(1, cv => { }, () => Promise.Resolved()));
            Assert.Throws<InvalidOperationException>(() => promise.Then(1, cv => 1, () => Promise.Resolved(1)));
            Assert.Throws<InvalidOperationException>(() => promise.Then(1, cv => Promise.Resolved(), () => Promise.Resolved()));
            Assert.Throws<InvalidOperationException>(() => promise.Then(1, cv => Promise.Resolved(1), () => Promise.Resolved(1)));

            Assert.Throws<InvalidOperationException>(() => promise.Then(() => { }, 1, cv => Promise.Resolved()));
            Assert.Throws<InvalidOperationException>(() => promise.Then(() => 1, 1, cv => Promise.Resolved(1)));
            Assert.Throws<InvalidOperationException>(() => promise.Then(() => Promise.Resolved(), 1, cv => Promise.Resolved()));
            Assert.Throws<InvalidOperationException>(() => promise.Then(() => Promise.Resolved(1), 1, cv => Promise.Resolved(1)));
            Assert.Throws<InvalidOperationException>(() => promise.Then(1, cv => { }, 1, cv => Promise.Resolved()));
            Assert.Throws<InvalidOperationException>(() => promise.Then(1, cv => 1, 1, cv => Promise.Resolved(1)));
            Assert.Throws<InvalidOperationException>(() => promise.Then(1, cv => Promise.Resolved(), 1, cv => Promise.Resolved()));
            Assert.Throws<InvalidOperationException>(() => promise.Then(1, cv => Promise.Resolved(1), 1, cv => Promise.Resolved(1)));

            Assert.Throws<InvalidOperationException>(() => promise.Then(() => { }, (object r) => Promise.Resolved()));
            Assert.Throws<InvalidOperationException>(() => promise.Then(() => 1, (object r) => Promise.Resolved(1)));
            Assert.Throws<InvalidOperationException>(() => promise.Then(() => Promise.Resolved(), (object r) => Promise.Resolved()));
            Assert.Throws<InvalidOperationException>(() => promise.Then(() => Promise.Resolved(1), (object r) => Promise.Resolved(1)));
            Assert.Throws<InvalidOperationException>(() => promise.Then(1, cv => { }, (object r) => Promise.Resolved()));
            Assert.Throws<InvalidOperationException>(() => promise.Then(1, cv => 1, (object r) => Promise.Resolved(1)));
            Assert.Throws<InvalidOperationException>(() => promise.Then(1, cv => Promise.Resolved(), (object r) => Promise.Resolved()));
            Assert.Throws<InvalidOperationException>(() => promise.Then(1, cv => Promise.Resolved(1), (object r) => Promise.Resolved(1)));

            Assert.Throws<InvalidOperationException>(() => promise.Then(() => { }, 1, (int cv, object r) => Promise.Resolved()));
            Assert.Throws<InvalidOperationException>(() => promise.Then(() => 1, 1, (int cv, object r) => Promise.Resolved(1)));
            Assert.Throws<InvalidOperationException>(() => promise.Then(() => Promise.Resolved(), 1, (int cv, object r) => Promise.Resolved()));
            Assert.Throws<InvalidOperationException>(() => promise.Then(() => Promise.Resolved(1), 1, (int cv, object r) => Promise.Resolved(1)));
            Assert.Throws<InvalidOperationException>(() => promise.Then(1, cv => { }, 1, (int cv, object r) => Promise.Resolved()));
            Assert.Throws<InvalidOperationException>(() => promise.Then(1, cv => 1, 1, (int cv, object r) => Promise.Resolved(1)));
            Assert.Throws<InvalidOperationException>(() => promise.Then(1, cv => Promise.Resolved(), 1, (int cv, object r) => Promise.Resolved()));
            Assert.Throws<InvalidOperationException>(() => promise.Then(1, cv => Promise.Resolved(1), 1, (int cv, object r) => Promise.Resolved(1)));

            deferred.Resolve();
        }

        [Test]
        public void PromiseIsInvalidAfterAwaited_T()
        {
            var deferred = Promise.NewDeferred<int>();
            var promise = deferred.Promise;

            Assert.IsTrue(promise.IsValid);

            promise.Then(v => { }).Forget();

            Assert.IsFalse(promise.IsValid);

#if CSHARP_7_3_OR_NEWER && PROMISE_DEBUG
            Assert.Throws<InvalidOperationException>(() => promise.GetAwaiter());
#endif
            Assert.Throws<InvalidOperationException>(() => promise.Preserve());
            Assert.Throws<InvalidOperationException>(() => promise.Forget());
            Assert.Throws<InvalidOperationException>(() => promise.Duplicate());

#if PROMISE_PROGRESS
            Assert.Throws<InvalidOperationException>(() => promise.Progress(v => { }));
            Assert.Throws<InvalidOperationException>(() => promise.Progress(1, (cv, v) => { }));
#endif
            Assert.Throws<InvalidOperationException>(() => promise.CatchCancelation(() => { }));
            Assert.Throws<InvalidOperationException>(() => promise.CatchCancelation(1, cv => { }));

            Assert.Throws<InvalidOperationException>(() => promise.Finally(() => { }));
            Assert.Throws<InvalidOperationException>(() => promise.Finally(1, cv => { }));

            Assert.Throws<InvalidOperationException>(() => promise.ContinueWith(r => { }));
            Assert.Throws<InvalidOperationException>(() => promise.ContinueWith(r => 1));
            Assert.Throws<InvalidOperationException>(() => promise.ContinueWith(r => Promise.Resolved()));
            Assert.Throws<InvalidOperationException>(() => promise.ContinueWith(r => Promise.Resolved(1)));
            Assert.Throws<InvalidOperationException>(() => promise.ContinueWith(1, (cv, r) => { }));
            Assert.Throws<InvalidOperationException>(() => promise.ContinueWith(1, (cv, r) => 1));
            Assert.Throws<InvalidOperationException>(() => promise.ContinueWith(1, (cv, r) => Promise.Resolved()));
            Assert.Throws<InvalidOperationException>(() => promise.ContinueWith(1, (cv, r) => Promise.Resolved(1)));

            Assert.Throws<InvalidOperationException>(() => promise.Catch(() => 1));
            Assert.Throws<InvalidOperationException>(() => promise.Catch(() => Promise.Resolved(1)));
            Assert.Throws<InvalidOperationException>(() => promise.Catch((object r) => 1));
            Assert.Throws<InvalidOperationException>(() => promise.Catch((object r) => Promise.Resolved(1)));
            Assert.Throws<InvalidOperationException>(() => promise.Catch(1, cv => 1));
            Assert.Throws<InvalidOperationException>(() => promise.Catch(1, cv => Promise.Resolved(1)));
            Assert.Throws<InvalidOperationException>(() => promise.Catch(1, (int cv, object r) => 1));
            Assert.Throws<InvalidOperationException>(() => promise.Catch(1, (int cv, object r) => Promise.Resolved(1)));

            Assert.Throws<InvalidOperationException>(() => promise.Then(v => { }));
            Assert.Throws<InvalidOperationException>(() => promise.Then(v => 1));
            Assert.Throws<InvalidOperationException>(() => promise.Then(v => Promise.Resolved()));
            Assert.Throws<InvalidOperationException>(() => promise.Then(v => Promise.Resolved(1)));
            Assert.Throws<InvalidOperationException>(() => promise.Then(1, (cv, v) => { }));
            Assert.Throws<InvalidOperationException>(() => promise.Then(1, (cv, v) => 1));
            Assert.Throws<InvalidOperationException>(() => promise.Then(1, (cv, v) => Promise.Resolved()));
            Assert.Throws<InvalidOperationException>(() => promise.Then(1, (cv, v) => Promise.Resolved(1)));

            Assert.Throws<InvalidOperationException>(() => promise.Then(v => { }, () => { }));
            Assert.Throws<InvalidOperationException>(() => promise.Then(v => 1, () => 1));
            Assert.Throws<InvalidOperationException>(() => promise.Then(v => Promise.Resolved(), () => { }));
            Assert.Throws<InvalidOperationException>(() => promise.Then(v => Promise.Resolved(1), () => 1));
            Assert.Throws<InvalidOperationException>(() => promise.Then(1, (cv, v) => { }, () => { }));
            Assert.Throws<InvalidOperationException>(() => promise.Then(1, (cv, v) => 1, () => 1));
            Assert.Throws<InvalidOperationException>(() => promise.Then(1, (cv, v) => Promise.Resolved(), () => { }));
            Assert.Throws<InvalidOperationException>(() => promise.Then(1, (cv, v) => Promise.Resolved(1), () => 1));

            Assert.Throws<InvalidOperationException>(() => promise.Then(v => { }, 1, cv => { }));
            Assert.Throws<InvalidOperationException>(() => promise.Then(v => 1, 1, cv => 1));
            Assert.Throws<InvalidOperationException>(() => promise.Then(v => Promise.Resolved(), 1, cv => { }));
            Assert.Throws<InvalidOperationException>(() => promise.Then(v => Promise.Resolved(1), 1, cv => 1));
            Assert.Throws<InvalidOperationException>(() => promise.Then(1, (cv, v) => { }, 1, cv => { }));
            Assert.Throws<InvalidOperationException>(() => promise.Then(1, (cv, v) => 1, 1, cv => 1));
            Assert.Throws<InvalidOperationException>(() => promise.Then(1, (cv, v) => Promise.Resolved(), 1, cv => { }));
            Assert.Throws<InvalidOperationException>(() => promise.Then(1, (cv, v) => Promise.Resolved(1), 1, cv => 1));

            Assert.Throws<InvalidOperationException>(() => promise.Then(v => { }, (object r) => { }));
            Assert.Throws<InvalidOperationException>(() => promise.Then(v => 1, (object r) => 1));
            Assert.Throws<InvalidOperationException>(() => promise.Then(v => Promise.Resolved(), (object r) => { }));
            Assert.Throws<InvalidOperationException>(() => promise.Then(v => Promise.Resolved(1), (object r) => 1));
            Assert.Throws<InvalidOperationException>(() => promise.Then(1, (cv, v) => { }, (object r) => { }));
            Assert.Throws<InvalidOperationException>(() => promise.Then(1, (cv, v) => 1, (object r) => 1));
            Assert.Throws<InvalidOperationException>(() => promise.Then(1, (cv, v) => Promise.Resolved(), (object r) => { }));
            Assert.Throws<InvalidOperationException>(() => promise.Then(1, (cv, v) => Promise.Resolved(1), (object r) => 1));

            Assert.Throws<InvalidOperationException>(() => promise.Then(v => { }, 1, (int cv, object r) => { }));
            Assert.Throws<InvalidOperationException>(() => promise.Then(v => 1, 1, (int cv, object r) => 1));
            Assert.Throws<InvalidOperationException>(() => promise.Then(v => Promise.Resolved(), 1, (int cv, object r) => { }));
            Assert.Throws<InvalidOperationException>(() => promise.Then(v => Promise.Resolved(1), 1, (int cv, object r) => 1));
            Assert.Throws<InvalidOperationException>(() => promise.Then(1, (cv, v) => { }, 1, (int cv, object r) => { }));
            Assert.Throws<InvalidOperationException>(() => promise.Then(1, (cv, v) => 1, 1, (int cv, object r) => 1));
            Assert.Throws<InvalidOperationException>(() => promise.Then(1, (cv, v) => Promise.Resolved(), 1, (int cv, object r) => { }));
            Assert.Throws<InvalidOperationException>(() => promise.Then(1, (cv, v) => Promise.Resolved(1), 1, (int cv, object r) => 1));

            Assert.Throws<InvalidOperationException>(() => promise.Then(v => { }, () => Promise.Resolved()));
            Assert.Throws<InvalidOperationException>(() => promise.Then(v => 1, () => Promise.Resolved(1)));
            Assert.Throws<InvalidOperationException>(() => promise.Then(v => Promise.Resolved(), () => Promise.Resolved()));
            Assert.Throws<InvalidOperationException>(() => promise.Then(v => Promise.Resolved(1), () => Promise.Resolved(1)));
            Assert.Throws<InvalidOperationException>(() => promise.Then(1, (cv, v) => { }, () => Promise.Resolved()));
            Assert.Throws<InvalidOperationException>(() => promise.Then(1, (cv, v) => 1, () => Promise.Resolved(1)));
            Assert.Throws<InvalidOperationException>(() => promise.Then(1, (cv, v) => Promise.Resolved(), () => Promise.Resolved()));
            Assert.Throws<InvalidOperationException>(() => promise.Then(1, (cv, v) => Promise.Resolved(1), () => Promise.Resolved(1)));

            Assert.Throws<InvalidOperationException>(() => promise.Then(v => { }, 1, cv => Promise.Resolved()));
            Assert.Throws<InvalidOperationException>(() => promise.Then(v => 1, 1, cv => Promise.Resolved(1)));
            Assert.Throws<InvalidOperationException>(() => promise.Then(v => Promise.Resolved(), 1, cv => Promise.Resolved()));
            Assert.Throws<InvalidOperationException>(() => promise.Then(v => Promise.Resolved(1), 1, cv => Promise.Resolved(1)));
            Assert.Throws<InvalidOperationException>(() => promise.Then(1, (cv, v) => { }, 1, cv => Promise.Resolved()));
            Assert.Throws<InvalidOperationException>(() => promise.Then(1, (cv, v) => 1, 1, cv => Promise.Resolved(1)));
            Assert.Throws<InvalidOperationException>(() => promise.Then(1, (cv, v) => Promise.Resolved(), 1, cv => Promise.Resolved()));
            Assert.Throws<InvalidOperationException>(() => promise.Then(1, (cv, v) => Promise.Resolved(1), 1, cv => Promise.Resolved(1)));

            Assert.Throws<InvalidOperationException>(() => promise.Then(v => { }, (object r) => Promise.Resolved()));
            Assert.Throws<InvalidOperationException>(() => promise.Then(v => 1, (object r) => Promise.Resolved(1)));
            Assert.Throws<InvalidOperationException>(() => promise.Then(v => Promise.Resolved(), (object r) => Promise.Resolved()));
            Assert.Throws<InvalidOperationException>(() => promise.Then(v => Promise.Resolved(1), (object r) => Promise.Resolved(1)));
            Assert.Throws<InvalidOperationException>(() => promise.Then(1, (cv, v) => { }, (object r) => Promise.Resolved()));
            Assert.Throws<InvalidOperationException>(() => promise.Then(1, (cv, v) => 1, (object r) => Promise.Resolved(1)));
            Assert.Throws<InvalidOperationException>(() => promise.Then(1, (cv, v) => Promise.Resolved(), (object r) => Promise.Resolved()));
            Assert.Throws<InvalidOperationException>(() => promise.Then(1, (cv, v) => Promise.Resolved(1), (object r) => Promise.Resolved(1)));

            Assert.Throws<InvalidOperationException>(() => promise.Then(v => { }, 1, (int cv, object r) => Promise.Resolved()));
            Assert.Throws<InvalidOperationException>(() => promise.Then(v => 1, 1, (int cv, object r) => Promise.Resolved(1)));
            Assert.Throws<InvalidOperationException>(() => promise.Then(v => Promise.Resolved(), 1, (int cv, object r) => Promise.Resolved()));
            Assert.Throws<InvalidOperationException>(() => promise.Then(v => Promise.Resolved(1), 1, (int cv, object r) => Promise.Resolved(1)));
            Assert.Throws<InvalidOperationException>(() => promise.Then(1, (cv, v) => { }, 1, (int cv, object r) => Promise.Resolved()));
            Assert.Throws<InvalidOperationException>(() => promise.Then(1, (cv, v) => 1, 1, (int cv, object r) => Promise.Resolved(1)));
            Assert.Throws<InvalidOperationException>(() => promise.Then(1, (cv, v) => Promise.Resolved(), 1, (int cv, object r) => Promise.Resolved()));
            Assert.Throws<InvalidOperationException>(() => promise.Then(1, (cv, v) => Promise.Resolved(1), 1, (int cv, object r) => Promise.Resolved(1)));

            deferred.Resolve(1);
        }

        [Test]
        public void ThrowingRejectExceptionInOnResolvedRejectsThePromiseWithTheGivenValue_void()
        {
            var promise = Promise.Resolved().Preserve();

            int rejectCount = 0;
            string expected = "Reject!";

            TestAction<Promise> onCallbackAdded = (ref Promise p) =>
                p.Catch((string e) =>
                {
                    Assert.AreEqual(expected, e);
                    ++rejectCount;
                }).Forget();
            TestAction<Promise<int>> onCallbackAddedConvert = (ref Promise<int> p) =>
            {
                p.Catch((string e) =>
                {
                    Assert.AreEqual(expected, e);
                    ++rejectCount;
                }).Forget();
            };

            TestHelper.AddResolveCallbacks<int, string>(promise,
                onResolve: () => { throw Promise.RejectException(expected); },
                onCallbackAdded: onCallbackAdded,
                onCallbackAddedConvert: onCallbackAddedConvert
            );
            TestHelper.AddCallbacks<int, object, string>(promise,
                onResolve: () => { throw Promise.RejectException(expected); },
                onCallbackAdded: onCallbackAdded,
                onCallbackAddedConvert: onCallbackAddedConvert
            );
            TestHelper.AddContinueCallbacks<int, string>(promise,
                onContinue: _ => { throw Promise.RejectException(expected); },
                onCallbackAdded: onCallbackAdded,
                onCallbackAddedConvert: onCallbackAddedConvert
            );

            Assert.AreEqual(
                (TestHelper.resolveVoidCallbacks + TestHelper.continueVoidCallbacks) * 2,
                rejectCount
            );

            promise.Forget();
        }

        [Test]
        public void ThrowingRejectExceptionInOnResolvedRejectsThePromiseWithTheGivenValue_T()
        {
            var promise = Promise.Resolved(100).Preserve();

            int rejectCount = 0;
            string expected = "Reject!";

            TestAction<Promise> onCallbackAdded = (ref Promise p) =>
                p.Catch((string e) =>
                {
                    Assert.AreEqual(expected, e);
                    ++rejectCount;
                }).Forget();
            TestAction<Promise<int>> onCallbackAddedConvert = (ref Promise<int> p) =>
                p.Catch((string e) =>
                {
                    Assert.AreEqual(expected, e);
                    ++rejectCount;
                }).Forget();

            TestHelper.AddResolveCallbacks<int, int, string>(promise,
                onResolve: v => { throw Promise.RejectException(expected); },
                onCallbackAdded: onCallbackAdded,
                onCallbackAddedConvert: onCallbackAddedConvert
            );
            TestHelper.AddCallbacks<int, int, object, string>(promise,
                onResolve: v => { throw Promise.RejectException(expected); },
                onCallbackAdded: onCallbackAdded,
                onCallbackAddedConvert: onCallbackAddedConvert
            );
            TestHelper.AddContinueCallbacks<int, int, string>(promise,
                onContinue: _ => { throw Promise.RejectException(expected); },
                onCallbackAdded: onCallbackAdded,
                onCallbackAddedConvert: onCallbackAddedConvert
            );

            Assert.AreEqual(
                (TestHelper.resolveTCallbacks + TestHelper.continueTCallbacks) * 2,
                rejectCount
            );

            promise.Forget();
        }

        [Test]
        public void ThrowingRejectExceptionInOnRejectedRejectsThePromiseWithTheGivenValue_void()
        {
            var promise = Promise.Rejected("A different reject value.").Preserve();

            int rejectCount = 0;
            string expected = "Reject!";

            TestAction<Promise> onCallbackAdded = (ref Promise p) =>
                p.Catch((string e) =>
                {
                    Assert.AreEqual(expected, e);
                    ++rejectCount;
                }).Forget();
            TestAction<Promise<int>> onCallbackAddedConvert = (ref Promise<int> p) =>
                p.Catch((string e) =>
                {
                    Assert.AreEqual(expected, e);
                    ++rejectCount;
                }).Forget();

            TestHelper.AddCallbacks<int, object, string>(promise,
                onReject: v => { throw Promise.RejectException(expected); },
                onUnknownRejection: () => { throw Promise.RejectException(expected); },
                onCallbackAdded: onCallbackAdded,
                onCallbackAddedConvert: onCallbackAddedConvert
            );
            TestHelper.AddContinueCallbacks<int, string>(promise,
                onContinue: _ => { throw Promise.RejectException(expected); },
                onCallbackAdded: onCallbackAdded,
                onCallbackAddedConvert: onCallbackAddedConvert
            );

            Assert.AreEqual(
                (TestHelper.rejectVoidCallbacks + TestHelper.continueVoidCallbacks) * 2,
                rejectCount
            );

            promise.Forget();
        }

        [Test]
        public void ThrowingRejectExceptionInOnRejectedRejectsThePromiseWithTheGivenValue_T()
        {
            var promise = Promise<int>.Rejected("A different reject value.").Preserve();

            int rejectCount = 0;
            string expected = "Reject!";

            TestAction<Promise> onCallbackAdded = (ref Promise p) =>
                p.Catch((string e) =>
                {
                    Assert.AreEqual(expected, e);
                    ++rejectCount;
                }).Forget();
            TestAction<Promise<int>> onCallbackAddedConvert = (ref Promise<int> p) =>
                p.Catch((string e) =>
                {
                    Assert.AreEqual(expected, e);
                    ++rejectCount;
                }).Forget();

            TestHelper.AddCallbacks<int, int, object, string>(promise,
                onReject: v => { throw Promise.RejectException(expected); },
                onUnknownRejection: () => { throw Promise.RejectException(expected); },
                onCallbackAdded: onCallbackAdded,
                onCallbackAddedConvert: onCallbackAddedConvert,
                onCallbackAddedT: onCallbackAddedConvert
            );
            TestHelper.AddContinueCallbacks<int, int, string>(promise,
                onContinue: _ => { throw Promise.RejectException(expected); },
                onCallbackAdded: onCallbackAdded,
                onCallbackAddedConvert: onCallbackAddedConvert
            );

            Assert.AreEqual(
                (TestHelper.rejectTCallbacks + TestHelper.continueTCallbacks) * 2,
                rejectCount
            );

            promise.Forget();
        }

        [Test]
        public void ThrowingCancelExceptionInOnResolvedCancelsThePromiseWithTheGivenValue_void()
        {
            var promise = Promise.Resolved().Preserve();

            int cancelCount = 0;

            System.Action onCancel = () =>
            {
                ++cancelCount;
            };

            TestHelper.AddResolveCallbacks<int, string>(promise,
                onResolve: () => { throw Promise.CancelException(); },
                onCancel: onCancel
            );
            TestHelper.AddCallbacks<int, object, string>(promise,
                onResolve: () => { throw Promise.CancelException(); },
                onCancel: onCancel
            );
            TestHelper.AddContinueCallbacks<int, string>(promise,
                onContinue: _ => { throw Promise.CancelException(); },
                onCancel: onCancel
            );

            Assert.AreEqual(
                (TestHelper.resolveVoidCallbacks + TestHelper.continueVoidCallbacks) * 2,
                cancelCount
            );

            promise.Forget();
        }

        [Test]
        public void ThrowingCancelExceptionInOnResolvedCancelsThePromiseWithTheGivenValue_T()
        {
            var promise = Promise.Resolved(100).Preserve();

            int cancelCount = 0;

            System.Action onCancel = () =>
            {
                ++cancelCount;
            };

            TestHelper.AddResolveCallbacks<int, bool, string>(promise,
                onResolve: v => { throw Promise.CancelException(); },
                onCancel: onCancel
            );
            TestHelper.AddCallbacks<int, bool, object, string>(promise,
                onResolve: v => { throw Promise.CancelException(); },
                onCancel: onCancel
            );
            TestHelper.AddContinueCallbacks<int, bool, string>(promise,
                onContinue: _ => { throw Promise.CancelException(); },
                onCancel: onCancel
            );

            Assert.AreEqual(
                (TestHelper.resolveTCallbacks + TestHelper.continueTCallbacks) * 2,
                cancelCount
            );

            promise.Forget();
        }

        [Test]
        public void ThrowingCancelExceptionInOnRejectedCancelsThePromiseWithTheGivenValue_void()
        {
            var promise = Promise.Rejected("Rejected").Preserve();

            int cancelCount = 0;

            System.Action onCancel = () =>
            {
                ++cancelCount;
            };

            TestHelper.AddCallbacks<int, object, string>(promise,
                onReject: v => { throw Promise.CancelException(); },
                onUnknownRejection: () => { throw Promise.CancelException(); },
                onCancel: onCancel
            );
            TestHelper.AddContinueCallbacks<int, string>(promise,
                onContinue: _ => { throw Promise.CancelException(); },
                onCancel: onCancel
            );

            Assert.AreEqual(
                (TestHelper.rejectVoidCallbacks + TestHelper.continueVoidCallbacks) * 2,
                cancelCount
            );

            promise.Forget();
        }

        [Test]
        public void ThrowingCancelExceptionInOnRejectedCancelsThePromiseWithTheGivenValue_T()
        {
            var promise = Promise<int>.Rejected("Rejected").Preserve();

            int cancelCount = 0;

            System.Action onCancel = () =>
            {
                ++cancelCount;
            };

            TestHelper.AddCallbacks<int, bool, object, string>(promise,
                onReject: v => { throw Promise.CancelException(); },
                onUnknownRejection: () => { throw Promise.CancelException(); },
                onCancel: onCancel
            );
            TestHelper.AddContinueCallbacks<int, int, string>(promise,
                onContinue: _ => { throw Promise.CancelException(); },
                onCancel: onCancel
            );

            Assert.AreEqual(
                (TestHelper.rejectTCallbacks + TestHelper.continueTCallbacks) * 2,
                cancelCount
            );

            promise.Forget();
        }

        [Test]
        public void ThrowingRethrowInOnResolvedRejectsThePromiseWithInvalidOperationException_void()
        {
            var promise = Promise.Resolved().Preserve();

            int errorCount = 0;

            TestAction<Promise> onCallbackAdded = (ref Promise p) =>
                p.Catch((object e) =>
                {
                    Assert.IsInstanceOf(typeof(InvalidOperationException), e);
                    ++errorCount;
                }).Forget();
            TestAction<Promise<int>> onCallbackAddedConvert = (ref Promise<int> p) =>
                p.Catch((object e) =>
                {
                    Assert.IsInstanceOf(typeof(InvalidOperationException), e);
                    ++errorCount;
                }).Forget();

            TestHelper.AddResolveCallbacks<int, string>(promise,
                onResolve: () => { throw Promise.Rethrow; },
                onCallbackAdded: onCallbackAdded,
                onCallbackAddedConvert: onCallbackAddedConvert
            );
            TestHelper.AddCallbacks<int, object, string>(promise,
                onResolve: () => { throw Promise.Rethrow; },
                onCallbackAdded: onCallbackAdded,
                onCallbackAddedConvert: onCallbackAddedConvert
            );
            TestHelper.AddContinueCallbacks<int, string>(promise,
                onContinue: _ => { throw Promise.Rethrow; },
                onCallbackAdded: onCallbackAdded,
                onCallbackAddedConvert: onCallbackAddedConvert
            );

            Assert.AreEqual(
                (TestHelper.resolveVoidCallbacks + TestHelper.continueVoidCallbacks) * 2,
                errorCount
            );

            promise.Forget();
        }

        [Test]
        public void ThrowingRethrowInOnResolvedRejectsThePromiseWithInvalidOperationException_T()
        {
            var promise = Promise.Resolved(100).Preserve();

            int errorCount = 0;

            TestAction<Promise> onCallbackAdded = (ref Promise p) =>
                p.Catch((object e) =>
                {
                    Assert.IsInstanceOf(typeof(InvalidOperationException), e);
                    ++errorCount;
                }).Forget();
            TestAction<Promise<int>> onCallbackAddedConvert = (ref Promise<int> p) =>
                p.Catch((object e) =>
                {
                    Assert.IsInstanceOf(typeof(InvalidOperationException), e);
                    ++errorCount;
                }).Forget();

            TestHelper.AddResolveCallbacks<int, int, string>(promise,
                onResolve: v => { throw Promise.Rethrow; },
                onCallbackAdded: onCallbackAdded,
                onCallbackAddedConvert: onCallbackAddedConvert
            );
            TestHelper.AddCallbacks<int, int, object, string>(promise,
                onResolve: v => { throw Promise.Rethrow; },
                onCallbackAdded: onCallbackAdded,
                onCallbackAddedConvert: onCallbackAddedConvert
            );
            TestHelper.AddContinueCallbacks<int, int, string>(promise,
                onContinue: _ => { throw Promise.Rethrow; },
                onCallbackAdded: onCallbackAdded,
                onCallbackAddedConvert: onCallbackAddedConvert
            );

            Assert.AreEqual(
                (TestHelper.resolveTCallbacks + TestHelper.continueTCallbacks) * 2,
                errorCount
            );

            promise.Forget();
        }

        [Test]
        public void ThrowingRethrowInOnRejectedRejectsThePromiseWithTheSameReason_void()
        {
            string expected = "Reject!";

            var promise = Promise.Rejected(expected).Preserve();

            int rejectCount = 0;

            TestAction<Promise> onCallbackAdded = (ref Promise p) =>
                p.Catch((string e) =>
                {
                    Assert.AreEqual(expected, e);
                    ++rejectCount;
                }).Forget();
            TestAction<Promise<int>> onCallbackAddedConvert = (ref Promise<int> p) =>
                p.Catch((string e) =>
                {
                    Assert.AreEqual(expected, e);
                    ++rejectCount;
                }).Forget();

            TestHelper.AddCallbacks<int, object, string>(promise,
                onReject: _ => { throw Promise.Rethrow; },
                onUnknownRejection: () => { throw Promise.Rethrow; },
                onCallbackAdded: onCallbackAdded,
                onCallbackAddedConvert: onCallbackAddedConvert
            );

            Assert.AreEqual(
                TestHelper.rejectVoidCallbacks * 2,
                rejectCount
            );

            promise.Forget();
        }

        [Test]
        public void ThrowingRethrowInOnRejectedRejectsThePromiseWithTheSameReason_T()
        {
            string expected = "Reject!";

            var promise = Promise<int>.Rejected(expected).Preserve();

            int rejectCount = 0;

            TestAction<Promise> onCallbackAdded = (ref Promise p) =>
                p.Catch((string e) =>
                {
                    Assert.AreEqual(expected, e);
                    ++rejectCount;
                }).Forget();
            TestAction<Promise<int>> onCallbackAddedConvert = (ref Promise<int> p) =>
                p.Catch((string e) =>
                {
                    Assert.AreEqual(expected, e);
                    ++rejectCount;
                }).Forget();

            TestHelper.AddCallbacks<int, int, object, string>(promise,
                onReject: _ => { throw Promise.Rethrow; },
                onUnknownRejection: () => { throw Promise.Rethrow; },
                onCallbackAdded: onCallbackAdded,
                onCallbackAddedConvert: onCallbackAddedConvert,
                onCallbackAddedT: onCallbackAddedConvert
            );

            Assert.AreEqual(
                TestHelper.rejectTCallbacks * 2,
                rejectCount
            );

            promise.Forget();
        }

        [Test]
        public void PromiseResolvedIsResolved()
        {
            bool resolved = false;

            Promise.Resolved()
                .CatchCancelation(() => Assert.Fail("Promise was canceled when it should have been resolved"))
                .Then(() => resolved = true, () => Assert.Fail("Promise was rejected when it should have been resolved"))
                .Forget();

            Assert.IsTrue(resolved);
        }

        [Test]
        public void PromiseResolvedIsResolvedWithTheGivenValue()
        {
            int expected = 100;
            bool resolved = false;

            Promise.Resolved(expected)
                .Then(val =>
                {
                    Assert.AreEqual(expected, val);
                    resolved = true;
                }, () => Assert.Fail("Promise was rejected when it should have been resolved"))
                .CatchCancelation(() => Assert.Fail("Promise was canceled when it should have been resolved"))
                .Forget();

            Assert.IsTrue(resolved);
        }

        [Test]
        public void PromiseRejectedIsRejectedWithTheGivenReason_void()
        {
            string expected = "Reject";
            bool rejected = false;

            Promise.Rejected(expected)
                .CatchCancelation(() => Assert.Fail("Promise was canceled when it should have been rejected"))
                .Then(() => Assert.Fail("Promise was resolved when it should have been rejected"),
                (object reason) =>
                {
                    Assert.AreEqual(expected, reason);
                    rejected = true;
                })
                .Forget();

            Assert.IsTrue(rejected);
        }

        [Test]
        public void PromiseRejectedIsRejectedWithTheGivenReason_T()
        {
            string expected = "Reject";
            bool rejected = false;

            Promise<int>.Rejected(expected)
                .CatchCancelation(() => Assert.Fail("Promise was canceled when it should have been rejected"))
                .Then(() => Assert.Fail("Promise was resolved when it should have been rejected"),
                (object reason) =>
                {
                    Assert.AreEqual(expected, reason);
                    rejected = true;
                })
                .Forget();

            Assert.IsTrue(rejected);
        }

        [Test]
        public void PromiseCanceledIsCanceled_void()
        {
            bool canceled = false;

            Promise.Canceled()
                .CatchCancelation(() =>
                {
                    canceled = true;
                })
                .Forget();

            Assert.IsTrue(canceled);
        }

        [Test]
        public void PromiseCanceledIsCanceled_T()
        {
            bool canceled = false;

            Promise<int>.Canceled()
                .CatchCancelation(() =>
                {
                    canceled = true;
                })
                .Forget();

            Assert.IsTrue(canceled);
        }

        [Test]
        public void PromiseSwitchToContextWorksProperly_Then(
            [Values(SynchronizationType.Foreground,
#if !UNITY_WEBGL
                SynchronizationType.Background,
#endif
                SynchronizationType.Explicit)] SynchronizationType synchronizationType,
            [Values(SynchronizationType.Foreground
#if !UNITY_WEBGL
                , SynchronizationType.Background
#endif
                )] SynchronizationType invokeContext,
            [Values] bool forceAsync)
        {
            Thread foregroundThread = Thread.CurrentThread;
            bool invoked = false;

            new ThreadHelper().ExecuteSynchronousOrOnThread(() =>
            {
                Promise promise = synchronizationType == SynchronizationType.Foreground
                    ? Promise.SwitchToForeground(forceAsync)
                    : synchronizationType == TestHelper.backgroundType
                    ? Promise.SwitchToBackground(forceAsync)
                    : Promise.SwitchToContext(TestHelper._foregroundContext, forceAsync);

                promise
                    .Then(() =>
                    {
                        TestHelper.AssertCallbackContext(synchronizationType, invokeContext, foregroundThread);
                        invoked = true;
                    })
                    .Forget();
            }, invokeContext == SynchronizationType.Foreground);

            TestHelper.ExecuteForegroundCallbacksAndWaitForThreadsToComplete();
            Assert.True(invoked);
        }

#if CSHARP_7_3_OR_NEWER
        [Test]
        public void PromiseSwitchToContextWorksProperly_Await(
            [Values(SynchronizationType.Foreground,
#if !UNITY_WEBGL
                SynchronizationType.Background,
#endif
                SynchronizationType.Explicit)] SynchronizationType synchronizationType,
            [Values(SynchronizationType.Foreground
#if !UNITY_WEBGL
                , SynchronizationType.Background
#endif
                )] SynchronizationType invokeContext,
            [Values] bool forceAsync)
        {
            Thread foregroundThread = Thread.CurrentThread;
            bool invoked = false;

            new ThreadHelper().ExecuteSynchronousOrOnThread(() =>
            {
                Await().Forget();

                async Promise Await()
                {
                    var contextSwitcher = synchronizationType == SynchronizationType.Foreground
                        ? Promise.SwitchToForegroundAwait(forceAsync)
                        : synchronizationType == TestHelper.backgroundType
                        ? Promise.SwitchToBackgroundAwait(forceAsync)
                        : Promise.SwitchToContextAwait(TestHelper._foregroundContext, forceAsync);
                    
                    await contextSwitcher;

                    TestHelper.AssertCallbackContext(synchronizationType, invokeContext, foregroundThread);
                    invoked = true;
                }
            }, invokeContext == SynchronizationType.Foreground);

            TestHelper.ExecuteForegroundCallbacksAndWaitForThreadsToComplete();
            Assert.True(invoked);
        }
#endif // CSHARP_7_3_OR_NEWER

#pragma warning disable CS0219 // The variable is assigned but its value is never used.
        [MethodImpl(MethodImplOptions.NoInlining)]
        private void CreatePromiseWithoutAwaitAndResetRuntimeContext()
        {
            var deferred = Promise.NewDeferred();
            var promise = deferred.Promise.Then(() => { });
            deferred.Resolve();
            Promise.Manager.ResetRuntimeContext();
        }

        [Test]
        public void ResetRuntimeContext_SuppressesUnobservedPromiseException()
        {
            CreatePromiseWithoutAwaitAndResetRuntimeContext();

            TestHelper.GcCollectAndWaitForFinalizers();
        }

        [MethodImpl(MethodImplOptions.NoInlining)]
        private void CreateAndDontHandleMultipleObjectsAndResetRuntimeContext()
        {
            var deferred = Promise.NewDeferred();
            var promise = deferred.Promise;
            promise.Then(() => { });
            try
            {
                promise.Then(() => { });
            }
            catch (System.InvalidOperationException)
            {
            }

            var cancelationSource = CancelationSource.New();

#if UNITY_2021_2_OR_NEWER || NETSTANDARD2_1_OR_GREATER || NETCOREAPP
            var asyncLock = new AsyncLock();
            var key = asyncLock.Lock();
            var keyPromise = asyncLock.LockAsync();
#endif

            Promise.Manager.ResetRuntimeContext();
        }

        [Test]
        public void ResetRuntimeContext_SuppressesMultipleUnhandledExceptions()
        {
            CreateAndDontHandleMultipleObjectsAndResetRuntimeContext();
            TestHelper.GcCollectAndWaitForFinalizers();
        }
#pragma warning restore CS0219 // The variable is assigned but its value is never used.

        [Test]
        public void PromiseMayBeResolvedWithNullable(
            [Values(10, 0, null)] int? expected)
        {
            var deferred = Promise.NewDeferred<int?>();
            deferred.Promise
                .Then(v => Assert.AreEqual(expected, v))
                .Forget();
            deferred.Resolve(expected);
        }

#if !UNITY_WEBGL
        private static readonly System.TimeSpan sleepTime = System.TimeSpan.FromSeconds(0.5);

        private static bool Wait(Promise promise, bool withTimeout)
        {
            if (withTimeout)
            {
                return promise.TryWait(System.TimeSpan.Zero);
            }
            promise.Wait();
            return true;
        }

        private static bool WaitNoThrow(Promise promise, out Promise.ResultContainer resultContainer, bool withTimeout)
        {
            if (withTimeout)
            {
                return promise.TryWaitNoThrow(System.TimeSpan.Zero, out resultContainer);
            }
            resultContainer = promise.WaitNoThrow();
            return true;
        }

        private static bool Wait<T>(Promise<T> promise, out T result, bool withTimeout)
        {
            if (withTimeout)
            {
                return promise.TryWaitForResult(System.TimeSpan.Zero, out result);
            }
            result = promise.WaitForResult();
            return true;
        }

        private static bool WaitNoThrow<T>(Promise<T> promise, out Promise<T>.ResultContainer resultContainer, bool withTimeout)
        {
            if (withTimeout)
            {
                return promise.TryWaitForResultNoThrow(System.TimeSpan.Zero, out resultContainer);
            }
            resultContainer = promise.WaitForResultNoThrow();
            return true;
        }

        [Test]
        public void PromiseWait_AlreadyCompleted_ReturnsSuccessfullyOrThrowsCorrectException(
            [Values(CompleteType.Resolve, CompleteType.Reject, CompleteType.Cancel)] CompleteType completeType,
            [Values] bool withTimeout)
        {
            var expectedException = completeType == CompleteType.Reject
                ? new InvalidOperationException("Test")
                : (System.Exception) Promise.CancelException();
            var promise = completeType == CompleteType.Resolve ? Promise.Resolved()
                : completeType == CompleteType.Reject ? Promise.Rejected(expectedException)
                : Promise.Canceled();
            bool didCatch = false;
            bool didNotTimeout = false;
            try
            {
                didNotTimeout = Wait(promise, withTimeout);
            }
            // The original exception is thrown in .Net 4.5+, but UnhandledException is thrown in old runtimes in order to preserve stack traces.
            catch (UnhandledException e)
            {
                didCatch = e.Value == expectedException;
            }
            catch (System.Exception e)
            {
                didCatch = completeType == CompleteType.Reject
                    ? e == expectedException
                    : e is CanceledException;
            }
            if (completeType == CompleteType.Resolve)
            {
                Assert.IsTrue(didNotTimeout);
            }
            Assert.AreNotEqual(completeType == CompleteType.Resolve, didCatch);
        }

        [Test]
        public void PromiseWaitNoThrow_AlreadyCompleted_ReturnsSuccessfullyWithProperResult(
            [Values(CompleteType.Resolve, CompleteType.Reject, CompleteType.Cancel)] CompleteType completeType,
            [Values] bool withTimeout)
        {
            string expectedRejection = "Rejected";
            var promise = completeType == CompleteType.Resolve ? Promise.Resolved()
                : completeType == CompleteType.Reject ? Promise.Rejected(expectedRejection)
                : Promise.Canceled();
            Promise.ResultContainer resultContainer;
            bool didNotTimeout = WaitNoThrow(promise, out resultContainer, withTimeout);
            Assert.True(didNotTimeout);
            Assert.AreEqual(completeType, (CompleteType) resultContainer.State);
            if (completeType == CompleteType.Reject)
            {
                Assert.AreEqual(expectedRejection, resultContainer.Reason);
            }
        }

        [Test]
        public void PromiseWait_DoesNotReturnUntilOperationIsComplete(
            [Values] bool alreadyComplete,
            [Values] bool withTimeout)
        {
            bool isExecuting = false;
            bool isComplete = false;

            var promise = Promise.Run(() =>
            {
                isExecuting = true;

                Thread.Sleep(sleepTime);

                isComplete = true;
            });

            SpinWait.SpinUntil(() => isExecuting);
            if (alreadyComplete)
            {
                Thread.Sleep(sleepTime.Add(sleepTime));
            }
            bool didNotTimeout = Wait(promise, withTimeout);
            bool expectedTimeout = withTimeout && !alreadyComplete;
            Assert.AreNotEqual(expectedTimeout, isComplete);
            Assert.AreNotEqual(expectedTimeout, didNotTimeout);
        }

        [Test]
        public void PromiseWaitNoThrow_DoesNotReturnUntilOperationIsComplete(
            [Values] bool alreadyComplete,
            [Values] bool withTimeout)
        {
            bool isExecuting = false;
            bool isComplete = false;

            var promise = Promise.Run(() =>
            {
                isExecuting = true;

                Thread.Sleep(sleepTime);

                isComplete = true;
            });

            SpinWait.SpinUntil(() => isExecuting);
            if (alreadyComplete)
            {
                Thread.Sleep(sleepTime.Add(sleepTime));
            }
            Promise.ResultContainer resultContainer;
            bool didNotTimeout = WaitNoThrow(promise, out resultContainer, withTimeout);
            bool expectedTimeout = withTimeout && !alreadyComplete;
            Assert.AreNotEqual(expectedTimeout, isComplete);
            Assert.AreNotEqual(expectedTimeout, didNotTimeout);
            if (!expectedTimeout)
            {
                Assert.AreEqual(Promise.State.Resolved, resultContainer.State);
            }
        }

        [Test]
        public void PromiseWait_DoesNotReturnUntilOperationIsComplete_AndThrowsCorrectException(
            [Values(CompleteType.Reject, CompleteType.Cancel)] CompleteType throwType,
            [Values] bool alreadyComplete,
            [Values] bool withTimeout)
        {
            bool isExecuting = false;
            bool isComplete = false;
            var expectedException = throwType == CompleteType.Reject
                ? new InvalidOperationException("Test")
                : (System.Exception) Promise.CancelException();

            TestHelper.s_expectedUncaughtRejectValue = expectedException;

            var promise = Promise.Run(() =>
            {
                isExecuting = true;

                Thread.Sleep(sleepTime);

                isComplete = true;
                throw expectedException;
            });

            SpinWait.SpinUntil(() => isExecuting);
            if (alreadyComplete)
            {
                Thread.Sleep(sleepTime.Add(sleepTime));
            }
            bool didCatch = false;
            bool didNotTimeout = false;
            try
            {
                didNotTimeout = Wait(promise, withTimeout);
            }
            // The original exception is thrown in .Net 4.5+, but UnhandledException is thrown in old runtimes in order to preserve stack traces.
            catch (UnhandledException e)
            {
                didCatch = e.Value == expectedException;
            }
            catch (System.Exception e)
            {
                didCatch = throwType == CompleteType.Reject
                    ? e == expectedException
                    : e is CanceledException;
            }
            bool expectedTimeout = withTimeout && !alreadyComplete;
            Assert.IsFalse(didNotTimeout);
            Assert.AreNotEqual(expectedTimeout, isComplete);
            Assert.AreNotEqual(expectedTimeout, didCatch);
        }

        [Test]
        public void PromiseWaitNoThrow_DoesNotReturnUntilOperationIsComplete_WithCorrectReason(
            [Values(CompleteType.Reject, CompleteType.Cancel)] CompleteType throwType,
            [Values] bool alreadyComplete,
            [Values] bool withTimeout)
        {
            bool isExecuting = false;
            bool isComplete = false;
            var expectedException = throwType == CompleteType.Reject
                ? new InvalidOperationException("Test")
                : (System.Exception) Promise.CancelException();

            TestHelper.s_expectedUncaughtRejectValue = expectedException;

            var promise = Promise.Run(() =>
            {
                isExecuting = true;

                Thread.Sleep(sleepTime);

                isComplete = true;
                throw expectedException;
            });

            SpinWait.SpinUntil(() => isExecuting);
            if (alreadyComplete)
            {
                Thread.Sleep(sleepTime.Add(sleepTime));
            }
            Promise.ResultContainer resultContainer;
            bool didNotTimeout = WaitNoThrow(promise, out resultContainer, withTimeout);
            bool expectedTimeout = withTimeout && !alreadyComplete;
            Assert.AreNotEqual(expectedTimeout, isComplete);
            Assert.AreNotEqual(expectedTimeout, didNotTimeout);
            if (!expectedTimeout)
            {
                Assert.AreEqual(throwType, (CompleteType) resultContainer.State);
                if (throwType == CompleteType.Reject)
                {
                    Assert.AreEqual(expectedException, resultContainer.Reason);
                }
            }
        }

        [Test]
        public void PromiseWaitForResult_AlreadyCompleted_ReturnsSuccessfullyOrThrowsCorrectException(
            [Values(CompleteType.Resolve, CompleteType.Reject, CompleteType.Cancel)] CompleteType completeType,
            [Values] bool withTimeout)
        {
            var expectedException = completeType == CompleteType.Reject
                ? new InvalidOperationException("Test")
                : (System.Exception) Promise.CancelException();
            int expectedResult = 42;
            var promise = completeType == CompleteType.Resolve ? Promise<int>.Resolved(expectedResult)
                : completeType == CompleteType.Reject ? Promise<int>.Rejected(expectedException)
                : Promise<int>.Canceled();
            bool didCatch = false;
            int result = -1;
            bool didNotTimeout = false;
            try
            {
                didNotTimeout = Wait(promise, out result, withTimeout);
            }
            // The original exception is thrown in .Net 4.5+, but UnhandledException is thrown in old runtimes in order to preserve stack traces.
            catch (UnhandledException e)
            {
                didCatch = e.Value == expectedException;
            }
            catch (System.Exception e)
            {
                didCatch = completeType == CompleteType.Reject
                    ? e == expectedException
                    : e is CanceledException;
            }
            if (completeType == CompleteType.Resolve)
            {
                Assert.IsTrue(didNotTimeout);
                Assert.AreEqual(expectedResult, result);
            }
            else
            {
                Assert.IsTrue(didCatch);
            }
        }

        [Test]
        public void PromiseWaitForResultNoThrow_AlreadyCompleted_ReturnsSuccessfullyWithProperResult(
            [Values(CompleteType.Resolve, CompleteType.Reject, CompleteType.Cancel)] CompleteType completeType,
            [Values] bool withTimeout)
        {
            var expectedException = completeType == CompleteType.Reject
                ? new InvalidOperationException("Test")
                : (System.Exception) Promise.CancelException();
            int expectedResult = 42;
            var promise = completeType == CompleteType.Resolve ? Promise<int>.Resolved(expectedResult)
                : completeType == CompleteType.Reject ? Promise<int>.Rejected(expectedException)
                : Promise<int>.Canceled();
            Promise<int>.ResultContainer resultContainer;
            bool didNotTimeout = WaitNoThrow(promise, out resultContainer, withTimeout);
            Assert.IsTrue(didNotTimeout);
            Assert.AreEqual(completeType, (CompleteType) resultContainer.State);
            if (completeType == CompleteType.Resolve)
            {
                Assert.AreEqual(expectedResult, resultContainer.Value);
            }
            else if (completeType == CompleteType.Reject)
            {
                Assert.AreEqual(expectedException, resultContainer.Reason);
            }
        }

        [Test]
        public void PromiseWaitForResult_DoesNotReturnUntilOperationIsComplete_AndReturnsWithCorrectResult(
            [Values] bool alreadyComplete,
            [Values] bool withTimeout)
        {
            bool isExecuting = false;
            bool isComplete = false;
            int expected = 42;

            var promise = Promise.Run(() =>
            {
                isExecuting = true;

                Thread.Sleep(sleepTime);

                isComplete = true;
                return expected;
            });

            SpinWait.SpinUntil(() => isExecuting);
            if (alreadyComplete)
            {
                Thread.Sleep(sleepTime.Add(sleepTime));
            }
            int result = -1;
            bool didNotTimeout = Wait(promise, out result, withTimeout);
            bool expectedTimeout = withTimeout && !alreadyComplete;
            Assert.AreNotEqual(expectedTimeout, isComplete);
            Assert.AreNotEqual(expectedTimeout, didNotTimeout);
            if (!expectedTimeout)
            {
                Assert.AreEqual(expected, result);
            }
        }

        [Test]
        public void PromiseWaitForResultNoThrow_DoesNotReturnUntilOperationIsComplete_AndReturnsWithCorrectResult(
            [Values] bool alreadyComplete,
            [Values] bool withTimeout)
        {
            bool isExecuting = false;
            bool isComplete = false;
            int expected = 42;

            var promise = Promise.Run(() =>
            {
                isExecuting = true;

                Thread.Sleep(sleepTime);

                isComplete = true;
                return expected;
            });

            SpinWait.SpinUntil(() => isExecuting);
            if (alreadyComplete)
            {
                Thread.Sleep(sleepTime.Add(sleepTime));
            }
            Promise<int>.ResultContainer resultContainer;
            bool didNotTimeout = WaitNoThrow(promise, out resultContainer, withTimeout);
            bool expectedTimeout = withTimeout && !alreadyComplete;
            Assert.AreNotEqual(expectedTimeout, isComplete);
            Assert.AreNotEqual(expectedTimeout, didNotTimeout);
            if (!expectedTimeout)
            {
                Assert.AreEqual(Promise.State.Resolved, resultContainer.State);
                Assert.AreEqual(expected, resultContainer.Value);
            }
        }

        [Test]
        public void PromiseWaitForResult_DoesNotReturnUntilOperationIsComplete_AndThrowsCorrectException(
            [Values(CompleteType.Reject, CompleteType.Cancel)] CompleteType throwType,
            [Values] bool alreadyComplete,
            [Values] bool withTimeout)
        {
            bool isExecuting = false;
            bool isComplete = false;
            var expectedException = throwType == CompleteType.Reject
                ? new InvalidOperationException("Test")
                : (System.Exception) Promise.CancelException();

            TestHelper.s_expectedUncaughtRejectValue = expectedException;

            var promise = Promise.Run(() =>
            {
                isExecuting = true;

                Thread.Sleep(sleepTime);

                isComplete = true;
                throw expectedException;
#pragma warning disable CS0162 // Unreachable code detected
                return 42;
#pragma warning restore CS0162 // Unreachable code detected
            });

            SpinWait.SpinUntil(() => isExecuting);
            if (alreadyComplete)
            {
                Thread.Sleep(sleepTime.Add(sleepTime));
            }
            bool didCatch = false;
            int result = -1;
            bool didNotTimeout = false;
            try
            {
                didNotTimeout = Wait(promise, out result, withTimeout);
            }
            // The original exception is thrown in .Net 4.5+, but UnhandledException is thrown in old runtimes in order to preserve stack traces.
            catch (UnhandledException e)
            {
                didCatch = e.Value == expectedException;
            }
            catch (System.Exception e)
            {
                didCatch = throwType == CompleteType.Reject
                    ? e == expectedException
                    : e is CanceledException;
            }
            bool expectedTimeout = withTimeout && !alreadyComplete;
            Assert.IsFalse(didNotTimeout);
            Assert.AreNotEqual(expectedTimeout, isComplete);
            Assert.AreNotEqual(expectedTimeout, didCatch);
        }

        [Test]
        public void PromiseWaitForResultNoThrow_DoesNotReturnUntilOperationIsComplete_WithCorrectReason(
            [Values(CompleteType.Reject, CompleteType.Cancel)] CompleteType throwType,
            [Values] bool alreadyComplete,
            [Values] bool withTimeout)
        {
            bool isExecuting = false;
            bool isComplete = false;
            var expectedException = throwType == CompleteType.Reject
                ? new InvalidOperationException("Test")
                : (System.Exception) Promise.CancelException();

            TestHelper.s_expectedUncaughtRejectValue = expectedException;

            var promise = Promise.Run(() =>
            {
                isExecuting = true;

                Thread.Sleep(sleepTime);

                isComplete = true;
                throw expectedException;
#pragma warning disable CS0162 // Unreachable code detected
                return 42;
#pragma warning restore CS0162 // Unreachable code detected
            });

            SpinWait.SpinUntil(() => isExecuting);
            if (alreadyComplete)
            {
                Thread.Sleep(sleepTime.Add(sleepTime));
            }
            Promise<int>.ResultContainer resultContainer;
            bool didNotTimeout = WaitNoThrow(promise, out resultContainer, withTimeout);
            bool expectedTimeout = withTimeout && !alreadyComplete;
            Assert.AreNotEqual(expectedTimeout, isComplete);
            Assert.AreNotEqual(expectedTimeout, didNotTimeout);
            if (!expectedTimeout)
            {
                Assert.AreEqual(throwType, (CompleteType) resultContainer.State);
                if (throwType == CompleteType.Reject)
                {
                    Assert.AreEqual(expectedException, resultContainer.Reason);
                }
            }
        }
#endif // !UNITY_WEBGL
    }
}